Workbook

Sheet ORIGINAL
A1: DEPARTAMENTO | B1: CIUDAD/MUNICIPIO | C1: UNIDAD | D1: TIPO UNIDAD | E1: CODIGO_CUADRANTE | F1: CUADRANTE | G1: NUMERO_CELULAR_CUADRANTE
A2: DEPARTAMENTO DE POLICIA AMAZONAS | B2: LETICIA | C2: ESTACION DE POLICIA LETICIA | D2: CAI ALAMEDA | E2: DEAMAMNVCCC01E01C06000001 | F2: 001 | G2: 3174655414
A3: DEPARTAMENTO DE POLICIA AMAZONAS | B3: LETICIA | C3: ESTACION DE POLICIA LETICIA | D3: CAI AFASINTE | E3: DEAMAMNVCCC01E01C07000002 | F3: 002 | G3: 3174654562
A4: DEPARTAMENTO DE POLICIA AMAZONAS | B4: LETICIA | C4: ESTACION DE POLICIA LETICIA | D4: CAI FRONTERA | E4: DEAMAMNVCCC01E01C08000003 | F4: 003 | G4: 3174655647
A5: DEPARTAMENTO DE POLICIA AMAZONAS | B5: LETICIA | C5: ESTACION DE POLICIA LETICIA | D5: CAI FRONTERA | E5: DEAMAMNVCCC01E01C08000004 | F5: 004 | G5: 3184601285
A6: DEPARTAMENTO DE POLICIA AMAZONAS | B6: LETICIA | C6: ESTACION DE POLICIA LETICIA | D6: SUBESTACION DE POLICIA SAN JOSE | E6: DEAMAMNVCCC01E01S01000001 | F6: 001 | G6: 3214263564
A7: DEPARTAMENTO DE POLICIA AMAZONAS | B7: LETICIA | C7: ESTACION DE POLICIA LETICIA | D7: SUBESTACION DE POLICIA SANTA SOFIA | E7: DEAMAMNVCCC01E01S02000001 | F7: 001 | G7: 3214921022
A8: DEPARTAMENTO DE POLICIA AMAZONAS | B8: LETICIA | C8: ESTACION DE POLICIA LETICIA | D8: SUBESTACION DE POLICIA LA PEDRERA | E8: DEAMAMNVCCC01E01S03000001 | F8: 001 | G8: 3102027219
A9: DEPARTAMENTO DE POLICIA AMAZONAS | B9: LETICIA | C9: ESTACION DE POLICIA LETICIA | D9: SUBESTACION DE POLICIA TARAPACA | E9: DEAMAMNVCCC01E01S04000001 | F9: 001 | G9: 3214921029
A10: DEPARTAMENTO DE POLICIA AMAZONAS | B10: LETICIA | C10: ESTACION DE POLICIA LETICIA | D10: SUBESTACION DE POLICIA PUERTO ARICA | E10: DEAMAMNVCCC01E01S05000001 | F10: 001 | G10: 3214921025
A11: DEPARTAMENTO DE POLICIA AMAZONAS | B11: PUERTO NARIÃ‘O | C11: ESTACION DE POLICIA PUERTO NARIÃ‘O | D11: ESTACION DE POLICIA PUERTO NARIÃ‘O | E11: DEAMAMNVCCC01E03000000001 | F11: 001 | G11: 3214921032
A12: DEPARTAMENTO DE POLICIA AMAZONAS | B12: PUERTO NARIÃ‘O | C12: ESTACION DE POLICIA PUERTO NARIÃ‘O | D12: SUBESTACION DE POLICIA SAN JUAN DE ATACUARI | E12: DEAMAMNVCCC01E03S01000001 | F12: 001 | G12: 3214921026
A13: DEPARTAMENTO DE POLICIA ANTIOQUIA | B13: ABEJORRAL | C13: ESTACION DE POLICIA ABEJORRAL | D13: ESTACION DE POLICIA ABEJORRAL | E13: DEANTMNVCCD06E01000000001 | F13: 001 | G13: 3137485217
... A2596: METROPOLITANA DE BOGOTA | B2596: KENNEDY | C2596: ESTACION DE POLICIA KENNEDY | D2596: CAI BRITALIA | E2596: MEBOGMNVCCC03E08C01000092 | F2596: 092 | G2596: 3008003405
A2597: METROPOLITANA DE BOGOTA | B2597: KENNEDY | C2597: ESTACION DE POLICIA KENNEDY | D2597: CAI BRITALIA | E2597: MEBOGMNVCCC03E08C01000119 | F2597: 119 | G2597: 3013460755
A2598: METROPOLITANA DE BOGOTA | B2598: KENNEDY | C2598: ESTACION DE POLICIA KENNEDY | D2598: CAI BRITALIA | E2598: MEBOGMNVCCC03E08C01000120 | F2598: 120 | G2598: 3013460752
A2599: METROPOLITANA DE BOGOTA | B2599: KENNEDY | C2599: ESTACION DE POLICIA KENNEDY | D2599: CAI BRITALIA | E2599: MEBOGMNVCCC03E08C01000121 | F2599: 121 | G2599: 3013460751
A2600: METROPOLITANA DE BOGOTA | B2600: KENNEDY | C2600: ESTACION DE POLICIA KENNEDY | D2600: CAI BRITALIA | E2600: MEBOGMNVCCC03E08C01000122 | F2600: 122 | G2600: 3013460750
A2601: METROPOLITANA DE BOGOTA | B2601: KENNEDY | C2601: ESTACION DE POLICIA KENNEDY | D2601: CAI CALDAS | E2601: MEBOGMNVCCC03E08C02000023 | F2601: 023 | G2601: 3002000063
A2602: METROPOLITANA DE BOGOTA | B2602: KENNEDY | C2602: ESTACION DE POLICIA KENNEDY | D2602: CAI CALDAS | E2602: MEBOGMNVCCC03E08C02000026 | F2602: 026 | G2602: 3017607954
A2603: METROPOLITANA DE BOGOTA | B2603: KENNEDY | C2603: ESTACION DE POLICIA KENNEDY | D2603: CAI CALDAS | E2603: MEBOGMNVCCC03E08C02000027 | F2603: 027 | G2603: 3007925915
A2604: METROPOLITANA DE BOGOTA | B2604: KENNEDY | C2604: ESTACION DE POLICIA KENNEDY | D2604: CAI CALDAS | E2604: MEBOGMNVCCC03E08C02000028 | F2604: 028 | G2604: 3007924831
A2605: METROPOLITANA DE BOGOTA | B2605: KENNEDY | C2605: ESTACION DE POLICIA KENNEDY | D2605: CAI CALDAS | E2605: MEBOGMNVCCC03E08C02000029 | F2605: 029 | G2605: 3017556427
A2606: METROPOLITANA DE BOGOTA | B2606: KENNEDY | C2606: ESTACION DE POLICIA KENNEDY | D2606: CAI CALDAS | E2606: MEBOGMNVCCC03E08C02000030 | F2606: 030 | G2606: 3007924846
A2607: METROPOLITANA DE BOGOTA | B2607: KENNEDY | C2607: ESTACION DE POLICIA KENNEDY | D2607: CAI CALDAS | E2607: MEBOGMNVCCC03E08C02000031 | F2607: 031 | G2607: 3017606877
A2608: METROPOLITANA DE BOGOTA | B2608: KENNEDY | C2608: ESTACION DE POLICIA KENNEDY | D2608: CAI CALDAS | E2608: MEBOGMNVCCC03E08C02000034 | F2608: 034 | G2608: 3002013734
A2609: METROPOLITANA DE BOGOTA | B2609: KENNEDY | C2609: ESTACION DE POLICIA KENNEDY | D2609: CAI CALDAS | E2609: MEBOGMNVCCC03E08C02000089 | F2609: 089 | G2609: 3002018556
A2610: METROPOLITANA DE BOGOTA | B2610: KENNEDY | C2610: ESTACION DE POLICIA KENNEDY | D2610: CAI CALDAS | E2610: MEBOGMNVCCC03E08C02000093 | F2610: 093 | G2610: 3002012297
A2611: METROPOLITANA DE BOGOTA | B2611: KENNEDY | C2611: ESTACION DE POLICIA KENNEDY | D2611: CAI CALDAS | E2611: MEBOGMNVCCC03E08C02000094 | F2611: 094 | G2611: 3002000653
A2612: METROPOLITANA DE BOGOTA | B2612: KENNEDY | C2612: ESTACION DE POLICIA KENNEDY | D2612: CAI CALDAS | E2612: MEBOGMNVCCC03E08C02000095 | F2612: 095 | G2612: 3008051965
A2613: METROPOLITANA DE BOGOTA | B2613: KENNEDY | C2613: ESTACION DE POLICIA KENNEDY | D2613: CAI CALDAS | E2613: MEBOGMNVCCC03E08C02000100 | F2613: 100 | G2613: 3007458651
A2614: METROPOLITANA DE BOGOTA | B2614: KENNEDY | C2614: ESTACION DE POLICIA KENNEDY | D2614: CAI CALDAS | E2614: MEBOGMNVCCC03E08C02000113 | F2614: 113 | G2614: 3013460773
A2615: METROPOLITANA DE BOGOTA | B2615: KENNEDY | C2615: ESTACION DE POLICIA KENNEDY | D2615: CAI CALDAS | E2615: MEBOGMNVCCC03E08C02000114 | F2615: 114 | G2615: 3013460770
A2616: METROPOLITANA DE BOGOTA | B2616: KENNEDY | C2616: ESTACION DE POLICIA KENNEDY | D2616: CAI CALDAS | E2616: MEBOGMNVCCC03E08C02000115 | F2616: 115 | G2616: 3013460768
A2617: METROPOLITANA DE BOGOTA | B2617: KENNEDY | C2617: ESTACION DE POLICIA KENNEDY | D2617: CAI CALDAS | E2617: MEBOGMNVCCC03E08C02000116 | F2617: 116 | G2617: 3013460767
A2618: METROPOLITANA DE BOGOTA | B2618: KENNEDY | C2618: ESTACION DE POLICIA KENNEDY | D2618: CAI CALDAS | E2618: MEBOGMNVCCC03E08C02000117 | F2618: 117 | G2618: 3013460764
A2619: METROPOLITANA DE BOGOTA | B2619: KENNEDY | C2619: ESTACION DE POLICIA KENNEDY | D2619: CAI CALDAS | E2619: MEBOGMNVCCC03E08C02000125 | F2619: 125 | G2619: 3508030003
A2620: METROPOLITANA DE BOGOTA | B2620: KENNEDY | C2620: ESTACION DE POLICIA KENNEDY | D2620: CAI CASTILLA | E2620: MEBOGMNVCCC03E08C03000032 | F2620: 032 | G2620: 3008051224
A2621: METROPOLITANA DE BOGOTA | B2621: KENNEDY | C2621: ESTACION DE POLICIA KENNEDY | D2621: CAI CASTILLA | E2621: MEBOGMNVCCC03E08C03000033 | F2621: 033 | G2621: 3008004061
A2622: METROPOLITANA DE BOGOTA | B2622: KENNEDY | C2622: ESTACION DE POLICIA KENNEDY | D2622: CAI CASTILLA | E2622: MEBOGMNVCCC03E08C03000035 | F2622: 035 | G2622: 3002014318
...

Sheet Hoja3
A1: Nombre de la unidad | B1: Direcci贸n de Referencia | C1: Latitud | D1: Longitud | E1: Teléfono
A2: CAI Villa del Sur | B2: Diagonal 23 # 26B-00, Villa Del Sur, Cali | C2: 34191 | D2: -765133 | E2: {=+VLOOKUP(A2,ORIGINAL!D3336:G3576,{4},FALSE)} -> 3105155709
A3: CAI San Marino | B3: Cl. 69 # 7C-4, San Marino / Fepicol, Cali | C3: 34633 | D3: -764952 | E3: {=+VLOOKUP(A3,ORIGINAL!D3337:G3577,{4},FALSE)} -> 3105325024
A4: ESTACION DE POLICIA EL GUABAL | B4: Cra. 44 # 14B-49, El Guabal, Cali | C4: 34258 | D4: -765298 | E4: {=+VLOOKUP(A4,ORIGINAL!D3338:G3578,{4},FALSE)} -> 3105325103
A5: CAI Mojica | B5: Cl. 82 # 28D-1, El Poblado II / Mojica, Cali | C5: 34189 | D5: -764862 | E5: {=+VLOOKUP(A5,ORIGINAL!D3339:G3579,{4},FALSE)} -> 3105238713
A6: CAI Paso del Comercio | B6: Cra. 1 Nte. con Cl. 73, Paso del Comercio, Cali | C6: 34795 | D6: -764921 | E6: {=+VLOOKUP(A6,ORIGINAL!D3340:G3580,{4},FALSE)} -> 3105305902
A7: CAI PETAR | B7: Cl. 73 con Cra. 4 Nte, Petar / Comuna 6, Cali | C7: 34786 | D7: -764816 | E7: {=+VLOOKUP(A7,ORIGINAL!D3341:G3581,{4},FALSE)} -> 3105296263
A8: CAI San Antonio | B8: Cra. 10 con Cl. 1 Oeste, San Cayetano, Cali | C8: 34449 | D8: -765442 | E8: {=+VLOOKUP(A8,ORIGINAL!D3342:G3582,{4},FALSE)} -> 3014670733
A9: CAI Loma de la Cruz | B9: Calle 5 con Carrera 16, Comuna 3, Cali | C9: 34426 | D9: -765414 | E9: {=+VLOOKUP(A9,ORIGINAL!D3343:G3583,{4},FALSE)} -> 3105287733
A10: CAI SAN NICOLAS | B10: Calle 20 esquina con Carrera 6, San Nicolás, Cali | C10: 34542 | D10: -765248 | E10: {=+VLOOKUP(A10,ORIGINAL!D3344:G3584,{4},FALSE)} -> 3105312699
A11: CAI Obrero | B11: Carrera 11B con Calle 22, El Obrero, Cali | C11: 34518 | D11: -765217 | E11: {=+VLOOKUP(A11,ORIGINAL!D3345:G3585,{4},FALSE)} -> 3105273858
A12: CAI Chipichape | B12: Avenida 6N con Calle 35N, San Vicente / Chipichape, Cali | C12: 34754 | D12: -765273 | E12: {=+VLOOKUP(A12,ORIGINAL!D3346:G3586,{4},FALSE)} -> 3105304022
A13: CAI La Merced | B13: Avenida 2N con Calle 52N, La Merced, Cali | C13: 34839 | D13: -765135 | E13: {=+VLOOKUP(A13,ORIGINAL!D3347:G3587,{4},FALSE)} -> 3105315875
... A59: Subestación de Policía La Elvira | B59: Corregimiento de La Elvira, zona rural norte de Cali | C59: 35185 | D59: -765912 | E59: {=+VLOOKUP(A59,ORIGINAL!D3393:G3633,{4},FALSE)} -> #N/A

Sheet Limpio
A1: Nombre de la unidad | B1: Dirección de Referencia | C1: Latitud | D1: Columna1 | E1: Columna2 | F1: Columna3 | G1: Teléfono
A2: CAI VILLA DEL SUR | B2: Cra. 46 #26b-156 a 26b-200, Villa Delsur, Cali, Valle del Cauca | C2: 3.409625557825613, -76.51880719315463 | D2: {=_xlfn.TEXTSPLIT(C2,",",,TRUE)} -> #VALUE! | G2: 3105155709
A3: CAI SAN MARINO | B3: Cl. 69 #7c-4, Fepicol, Cali, Valle del Cauca | C3: 3.4626163129212912, -76.48553405105038 | D3: {=_xlfn.TEXTSPLIT(C3,",")} -> #VALUE! | G3: 3105325024
A4: ESTACION DE POLICIA EL GUABAL | B4: Cra. 44 #14B-49, Comuna 10, Cali, Valle del Cauca | C4: 3.412968551999918, -76.52733812194757 | D4: {=_xlfn.TEXTSPLIT(C4,",")} -> #VALUE! | G4: 3105325103
A5: CAI MOJICA | B5: Cl. 82 #28d-1-157, El Poblado II, Cali, Valle del Cauca | C5: 3.41760342322223, -76.48608187479316 | D5: {=_xlfn.TEXTSPLIT(C5,",")} -> #VALUE! | G5: 3105238713
A6: CAI PASO DEL COMERCIO | B6: 3.4920014747832138, -76.48572193880999 | C6: 3.4920014747832138, -76.48572193880999 | D6: {=_xlfn.TEXTSPLIT(C6,",")} -> #VALUE! | G6: 3105305902
A7: CAI PETAR | B7: Cl. 73, Jorge Eliecer Gaitan, Cali, Palmira, Valle del Cauca | C7: 3.4716621587652563, -76.48218684114276 | D7: {=_xlfn.TEXTSPLIT(C7,",")} -> #VALUE! | G7: 3105296263
A8: CAI SAN ANTONIO | B8: Carrera 10 #Calle 1 Oeste, Cali, Valle del Cauca | C8: 3.4469498545745343, -76.5416812644106 | D8: {=_xlfn.TEXTSPLIT(C8,",")} -> #VALUE! | G8: 3014670733
A9: CAI LOMA DE LA CRUZ | B9: Carrera 16A Esquina Calle 5, COMUNA 3, Cali, Valle del Cauca | C9: 3.4430170539777896, -76.53746624766211 | D9: {=_xlfn.TEXTSPLIT(C9,",")} -> #VALUE! | G9: 3105287733
A10: CAI SAN NICOLAS | B10: Avenida 6 #19-20, COMUNA 3, Cali, Valle del Cauca | C10: 3.4542301730230243, -76.52512867891481 | D10: {=_xlfn.TEXTSPLIT(C10,",")} -> #VALUE! | G10: 3105312699
A11: CAI OBRERO | B11: Cra. 10 #22a-56 a 22a-104, Cali, Valle del Cauca | C11: 3.4495927991033373, -76.52048265845596 | D11: {=_xlfn.TEXTSPLIT(C11,",")} -> #VALUE! | G11: 3105273858
A12: CAI CHIPICHAPE | B12: Av. 6 Bis Nte. #35 Norte34, San Vicente, Cali, Valle del Cauca | C12: 3.4727672994800236, -76.52633769494443 | D12: {=_xlfn.TEXTSPLIT(C12,",")} -> #VALUE! | G12: 3105304022
A13: CAI LA MERCED | B13: Avenida 2N con Calle 52N, La Merced, Cali, Valle del Cauca | C13: 3.4815196103289923, -76.50939857378494 | D13: {=_xlfn.TEXTSPLIT(C13,",")} -> #VALUE! | G13: 3105315875
A14: CAI PLAZA NORTE | B14: Cl. 44 Nte. #2g Norte-109 a 2g Norte-49, La Merced, Cali, Valle del Cauca | C14: 3.4776669191330982, -76.51686787298793 | D14: {=_xlfn.TEXTSPLIT(C14,",")} -> #VALUE! | G14: 3105316935
... A32: SUBESTACION DE POLICIA PICHINDE | B32: Corregimiento de Pichindé, zona rural de Cali | C32: 3.433635607239425, -76.61669073450604 | D32: {=_xlfn.TEXTSPLIT(C32,",")} -> #VALUE! | G32: 3508191673
A33: CAI CIUDAD JARDÍN | B33: Carrera 102 con Calle 16, Ciudad Jardín, Cali | C33: 3.3655104614050653, -76.53111293667624 | D33: {=_xlfn.TEXTSPLIT(C33,",")} -> #VALUE! | G33: (602) 5552915
A34: SUBESTACIÓN DE POLICÍA VORÁGINE | B34: Corregimiento de Pance (Sector La Vorágine), Cali | C34: 3.3467831706460434, -76.58950644799849 | D34: {=_xlfn.TEXTSPLIT(C34,",")} -> #VALUE! | G34: (602) 5500313
A35: CAI SALOMIA | B35: Carrera 5, Calle 52, Nueva Salomia, Cra. 5 #52, Cali, Valle del Cauca | C35: 3.463552938921968, -76.50052581484242 | D35: {=_xlfn.TEXTSPLIT(C35,",")} -> #VALUE! | G35: 3105281384
A36: CAI METROPOLITANO | B36: Cl. 69 #1-203, Villa del Sol, Cali, Valle del Cauca | C36: 3.4851693399517356, -76.4942986568768 | D36: {=_xlfn.TEXTSPLIT(C36,",")} -> #VALUE! | G36: 3105286734
A37: CAI CIUDAD 2000 | B37: Calle 42 (Av. Ciudad de Cali) con Carrera 84, Ciudad 2000, Cali | C37: 3.3960618552382935, -76.52397194806544 | D37: {=_xlfn.TEXTSPLIT(C37,",")} -> #VALUE! | G37: 3105118886
A38: CAI NAPOLES | B38: Calle 2A con Carrera 77, Las Farallones / Nápoles, Cali | C38: 3.3890577252776515, -76.5512401279646 | D38: {=_xlfn.TEXTSPLIT(C38,",")} -> #VALUE! | G38: 3105287793
A39: SUBESTACION DE POLICIA LA BUITRERA | B39: Corregimiento La Buitrera (Sector Centro), Cali | C39: 3.364148628365583, -76.56261002318361 | D39: {=_xlfn.TEXTSPLIT(C39,",")} -> #VALUE! | G39: 3508191672
A40: ESTACION DE POLICIA NUEVA FLORESTA | B40: Cl. 44 #241, Cali, Valle del Cauca | C40: 3.4384249584297266, -76.5006917345061 | D40: {=_xlfn.TEXTSPLIT(C40,",")} -> #VALUE! | G40: 3105136985
A41: Estación de policía Meléndez | B41: Cl. 4 #93-00, Bajo Jordan, Cali, Valle del Cauca | C41: 3.375895900031209, -76.54751716713456 | D41: {=_xlfn.TEXTSPLIT(C41,",")} -> #VALUE! | G41: 3105304979
A42: Estación de policía El Caney | B42: Cra. 81 #47-33 esq, Comuna 17, Cali, Valle del Cauca | C42: 3.3874581721228076, -76.51674053867012 | D42: {=_xlfn.TEXTSPLIT(C42,",")} -> #VALUE! | G42: 3105300658
A43: CAI Limonar | B43: Cl. 13b #64-00, Comuna 17, Cali, Valle del Cauca | C43: 3.4025115338512024, -76.53470482113397 | D43: {=_xlfn.TEXTSPLIT(C43,",")} -> #VALUE! | G43: 3105300623
A44: CAI Llano Verde | B44: Cl 56G con Kr 47D, Cali, Valle del Cauca | C44: 3.392458942860606, -76.5069442575103 | D44: {=_xlfn.TEXTSPLIT(C44,",")} -> #VALUE! | G44: 301 4645015
A45: CAI Puerto Rellena | B45: Cra. 46 #26b-156 a 26b-200, Villa Delsur, Cali, Valle del Cauca | C45: 3.4096253665669267, -76.51880736174832 | D45: {=_xlfn.TEXTSPLIT(C45,",")} -> #VALUE! | G45: 3101515709
